Workbook

Sheet Sales
A1: Order no. | B1: Date | C1: Region | D1: Salesperson | E1: Category | F1: Unit Sold | G1: Unit Price | H1: Status | I1: Month | J1: Revenue After Returns | K1: Product | L1: Total Sales | M1: Month Number
A2: ORD-1 | B2: 11/30/2024 | C2: East | D2: Drusie Stedmond | E2: =IF(OR(K2="iPhone 15",K2="Samsung Galaxy"),"Mobiles",IF(OR(K2="HP Laptop",K2="Dell Laptop"),"Laptops","Accessories")) -> Accessories | F2: 14 | G2: 8148 | H2: Returned | I2: =TEXT(DATE(MID(B2,7,4),LEFT(B2,2),MID(B2,4,2)),"MMM") -> Nov | J2: =if(H2="Returned",0,L2) -> 0 | K2: Logitech Mouse | L2: 114072 | M2: =MONTH(DATE(MID(B2,7,4),LEFT(B2,2),MID(B2,4,2))) -> 11
A3: ORD-2 | B3: 07/29/2024 | C3: West | D3: Piggy Charlewood | E3: =IF(OR(K3="iPhone 15",K3="Samsung Galaxy"),"Mobiles",IF(OR(K3="HP Laptop",K3="Dell Laptop"),"Laptops","Accessories")) -> Accessories | F3: 3 | G3: 74394 | H3: Pending | I3: =TEXT(DATE(MID(B3,7,4),LEFT(B3,2),MID(B3,4,2)),"MMM") -> Jul | J3: =if(H3="Returned",0,L3) -> 223182 | K3: Boat Earbuds | L3: 223182 | M3: =MONTH(DATE(MID(B3,7,4),LEFT(B3,2),MID(B3,4,2))) -> 7
A4: ORD-3 | B4: 04/14/2024 | C4: South | D4: Duky Ronisch | E4: =IF(OR(K4="iPhone 15",K4="Samsung Galaxy"),"Mobiles",IF(OR(K4="HP Laptop",K4="Dell Laptop"),"Laptops","Accessories")) -> Mobiles | F4: 19 | G4: 59294 | H4: Completed | I4: =TEXT(DATE(MID(B4,7,4),LEFT(B4,2),MID(B4,4,2)),"MMM") -> Apr | J4: =if(H4="Returned",0,L4) -> 1126586 | K4: iPhone 15 | L4: 1126586 | M4: =MONTH(DATE(MID(B4,7,4),LEFT(B4,2),MID(B4,4,2))) -> 4
A5: ORD-4 | B5: 45507 | C5: West | D5: Gabe Howell | E5: =IF(OR(K5="iPhone 15",K5="Samsung Galaxy"),"Mobiles",IF(OR(K5="HP Laptop",K5="Dell Laptop"),"Laptops","Accessories")) -> Laptops | F5: 1 | G5: 63918 | H5: Pending | I5: =TEXT(DATE(MID(B5,7,4),LEFT(B5,2),MID(B5,4,2)),"MMM") -> Mar | J5: =if(H5="Returned",0,L5) -> 63918 | K5: HP Laptop | L5: 63918 | M5: =MONTH(DATE(MID(B5,7,4),LEFT(B5,2),MID(B5,4,2))) -> 3
A6: ORD-5 | B6: 07/31/2024 | C6: East | D6: Burr Jago | E6: =IF(OR(K6="iPhone 15",K6="Samsung Galaxy"),"Mobiles",IF(OR(K6="HP Laptop",K6="Dell Laptop"),"Laptops","Accessories")) -> Accessories | F6: 1 | G6: 75554 | H6: Returned | I6: =TEXT(DATE(MID(B6,7,4),LEFT(B6,2),MID(B6,4,2)),"MMM") -> Jul | J6: =if(H6="Returned",0,L6) -> 0 | K6: Boat Earbuds | L6: 75554 | M6: =MONTH(DATE(MID(B6,7,4),LEFT(B6,2),MID(B6,4,2))) -> 7
A7: ORD-6 | B7: 45629 | C7: South | D7: Wenonah Hallatt | E7: =IF(OR(K7="iPhone 15",K7="Samsung Galaxy"),"Mobiles",IF(OR(K7="HP Laptop",K7="Dell Laptop"),"Laptops","Accessories")) -> Laptops | F7: 3 | G7: 31893 | H7: Pending | I7: =TEXT(DATE(MID(B7,7,4),LEFT(B7,2),MID(B7,4,2)),"MMM") -> Mar | J7: =if(H7="Returned",0,L7) -> 95679 | K7: Dell Laptop | L7: 95679 | M7: =MONTH(DATE(MID(B7,7,4),LEFT(B7,2),MID(B7,4,2))) -> 3
A8: ORD-7 | B8: 10/22/2024 | C8: West | D8: Lurette Heavyside | E8: =IF(OR(K8="iPhone 15",K8="Samsung Galaxy"),"Mobiles",IF(OR(K8="HP Laptop",K8="Dell Laptop"),"Laptops","Accessories")) -> Laptops | F8: 16 | G8: 78420 | H8: Completed | I8: =TEXT(DATE(MID(B8,7,4),LEFT(B8,2),MID(B8,4,2)),"MMM") -> Oct | J8: =if(H8="Returned",0,L8) -> 1254720 | K8: Dell Laptop | L8: 1254720 | M8: =MONTH(DATE(MID(B8,7,4),LEFT(B8,2),MID(B8,4,2))) -> 10
A9: ORD-8 | B9: 06/16/2024 | C9: East | D9: Malcolm Poulsum | E9: =IF(OR(K9="iPhone 15",K9="Samsung Galaxy"),"Mobiles",IF(OR(K9="HP Laptop",K9="Dell Laptop"),"Laptops","Accessories")) -> Laptops | F9: 6 | G9: 56487 | H9: Completed | I9: =TEXT(DATE(MID(B9,7,4),LEFT(B9,2),MID(B9,4,2)),"MMM") -> Jun | J9: =if(H9="Returned",0,L9) -> 338922 | K9: Dell Laptop | L9: 338922 | M9: =MONTH(DATE(MID(B9,7,4),LEFT(B9,2),MID(B9,4,2))) -> 6
A10: ORD-9 | B10: 02/15/2024 | C10: East | D10: Carr Prisley | E10: =IF(OR(K10="iPhone 15",K10="Samsung Galaxy"),"Mobiles",IF(OR(K10="HP Laptop",K10="Dell Laptop"),"Laptops","Accessories")) -> Mobiles | F10: 2 | G10: 12129 | H10: Returned | I10: =TEXT(DATE(MID(B10,7,4),LEFT(B10,2),MID(B10,4,2)),"MMM") -> Feb | J10: =if(H10="Returned",0,L10) -> 0 | K10: Samsung Galaxy | L10: 24258 | M10: =MONTH(DATE(MID(B10,7,4),LEFT(B10,2),MID(B10,4,2))) -> 2
A11: ORD-10 | B11: 45447 | C11: East | D11: Chickie Dayley | E11: =IF(OR(K11="iPhone 15",K11="Samsung Galaxy"),"Mobiles",IF(OR(K11="HP Laptop",K11="Dell Laptop"),"Laptops","Accessories")) -> Accessories | F11: 18 | G11: 4204 | H11: Returned | I11: =TEXT(DATE(MID(B11,7,4),LEFT(B11,2),MID(B11,4,2)),"MMM") -> Apr | J11: =if(H11="Returned",0,L11) -> 0 | K11: OnePlus TV | L11: 75672 | M11: =MONTH(DATE(MID(B11,7,4),LEFT(B11,2),MID(B11,4,2))) -> 4
A12: ORD-11 | B12: 45352 | C12: North | D12: Annalise Plowman | E12: =IF(OR(K12="iPhone 15",K12="Samsung Galaxy"),"Mobiles",IF(OR(K12="HP Laptop",K12="Dell Laptop"),"Laptops","Accessories")) -> Accessories | F12: 13 | G12: 22388 | H12: Pending | I12: =TEXT(DATE(MID(B12,7,4),LEFT(B12,2),MID(B12,4,2)),"MMM") -> Jan | J12: =if(H12="Returned",0,L12) -> 291044 | K12: Logitech Mouse | L12: 291044 | M12: =MONTH(DATE(MID(B12,7,4),LEFT(B12,2),MID(B12,4,2))) -> 1
A13: ORD-12 | B13: 09/21/2024 | C13: North | D13: Janessa Bladder | E13: =IF(OR(K13="iPhone 15",K13="Samsung Galaxy"),"Mobiles",IF(OR(K13="HP Laptop",K13="Dell Laptop"),"Laptops","Accessories")) -> Mobiles | F13: 14 | G13: 71188 | H13: Returned | I13: =TEXT(DATE(MID(B13,7,4),LEFT(B13,2),MID(B13,4,2)),"MMM") -> Sep | J13: =if(H13="Returned",0,L13) -> 0 | K13: iPhone 15 | L13: 996632 | M13: =MONTH(DATE(MID(B13,7,4),LEFT(B13,2),MID(B13,4,2))) -> 9
A14: ORD-13 | B14: 45297 | C14: South | D14: Orrin Suarez | E14: =IF(OR(K14="iPhone 15",K14="Samsung Galaxy"),"Mobiles",IF(OR(K14="HP Laptop",K14="Dell Laptop"),"Laptops","Accessories")) -> Laptops | F14: 16 | G14: 10359 | H14: Completed | I14: =TEXT(DATE(MID(B14,7,4),LEFT(B14,2),MID(B14,4,2)),"MMM") -> Jun | J14: =if(H14="Returned",0,L14) -> 165744 | K14: HP Laptop | L14: 165744 | M14: =MONTH(DATE(MID(B14,7,4),LEFT(B14,2),MID(B14,4,2))) -> 6
A15: ORD-14 | B15: 12/15/2024 | C15: East | D15: Fallon Simonassi | E15: =IF(OR(K15="iPhone 15",K15="Samsung Galaxy"),"Mobiles",IF(OR(K15="HP Laptop",K15="Dell Laptop"),"Laptops","Accessories")) -> Mobiles | F15: 13 | G15: 21620 | H15: Pending | I15: =TEXT(DATE(MID(B15,7,4),LEFT(B15,2),MID(B15,4,2)),"MMM") -> Dec | J15: =if(H15="Returned",0,L15) -> 281060 | K15: Samsung Galaxy | L15: 281060 | M15: =MONTH(DATE(MID(B15,7,4),LEFT(B15,2),MID(B15,4,2))) -> 12
A16: ORD-15 | B16: 11/20/2024 | C16: North | D16: Bobinette Lakenton | E16: =IF(OR(K16="iPhone 15",K16="Samsung Galaxy"),"Mobiles",IF(OR(K16="HP Laptop",K16="Dell Laptop"),"Laptops","Accessories")) -> Accessories | F16: 5 | G16: 45721 | H16: Returned | I16: =TEXT(DATE(MID(B16,7,4),LEFT(B16,2),MID(B16,4,2)),"MMM") -> Nov | J16: =if(H16="Returned",0,L16) -> 0 | K16: OnePlus TV | L16: 228605 | M16: =MONTH(DATE(MID(B16,7,4),LEFT(B16,2),MID(B16,4,2))) -> 11
A17: ORD-16 | B17: 45602 | C17: North | D17: Elisabeth Give | E17: =IF(OR(K17="iPhone 15",K17="Samsung Galaxy"),"Mobiles",IF(OR(K17="HP Laptop",K17="Dell Laptop"),"Laptops","Accessories")) -> Accessories | F17: 17 | G17: 19213 | H17: Pending | I17: =TEXT(DATE(MID(B17,7,4),LEFT(B17,2),MID(B17,4,2)),"MMM") -> Jun | J17: =if(H17="Returned",0,L17) -> 326621 | K17: OnePlus TV | L17: 326621 | M17: =MONTH(DATE(MID(B17,7,4),LEFT(B17,2),MID(B17,4,2))) -> 6
A18: ORD-17 | B18: 12/29/2024 | C18: East | D18: Meggi Bodechon | E18: =IF(OR(K18="iPhone 15",K18="Samsung Galaxy"),"Mobiles",IF(OR(K18="HP Laptop",K18="Dell Laptop"),"Laptops","Accessories")) -> Accessories | F18: 5 | G18: 16412 | H18: Pending | I18: =TEXT(DATE(MID(B18,7,4),LEFT(B18,2),MID(B18,4,2)),"MMM") -> Dec | J18: =if(H18="Returned",0,L18) -> 82060 | K18: Logitech Mouse | L18: 82060 | M18: =MONTH(DATE(MID(B18,7,4),LEFT(B18,2),MID(B18,4,2))) -> 12
A19: ORD-18 | B19: 01/14/2024 | C19: South | D19: Lorrie Rogers | E19: =IF(OR(K19="iPhone 15",K19="Samsung Galaxy"),"Mobiles",IF(OR(K19="HP Laptop",K19="Dell Laptop"),"Laptops","Accessories")) -> Laptops | F19: 19 | G19: 47133 | H19: Completed | I19: =TEXT(DATE(MID(B19,7,4),LEFT(B19,2),MID(B19,4,2)),"MMM") -> Jan | J19: =if(H19="Returned",0,L19) -> 895527 | K19: HP Laptop | L19: 895527 | M19: =MONTH(DATE(MID(B19,7,4),LEFT(B19,2),MID(B19,4,2))) -> 1
A20: ORD-19 | B20: 12/23/2024 | C20: North | D20: Avictor Curreen | E20: =IF(OR(K20="iPhone 15",K20="Samsung Galaxy"),"Mobiles",IF(OR(K20="HP Laptop",K20="Dell Laptop"),"Laptops","Accessories")) -> Accessories | F20: 6 | G20: 32588 | H20: Returned | I20: =TEXT(DATE(MID(B20,7,4),LEFT(B20,2),MID(B20,4,2)),"MMM") -> Dec | J20: =if(H20="Returned",0,L20) -> 0 | K20: Logitech Mouse | L20: 195528 | M20: =MONTH(DATE(MID(B20,7,4),LEFT(B20,2),MID(B20,4,2))) -> 12
A21: ORD-20 | B21: 04/26/2024 | C21: South | D21: Zilvia Muat | E21: =IF(OR(K21="iPhone 15",K21="Samsung Galaxy"),"Mobiles",IF(OR(K21="HP Laptop",K21="Dell Laptop"),"Laptops","Accessories")) -> Accessories | F21: 5 | G21: 22173 | H21: Pending | I21: =TEXT(DATE(MID(B21,7,4),LEFT(B21,2),MID(B21,4,2)),"MMM") -> Apr | J21: =if(H21="Returned",0,L21) -> 110865 | K21: Logitech Mouse | L21: 110865 | M21: =MONTH(DATE(MID(B21,7,4),LEFT(B21,2),MID(B21,4,2))) -> 4
A22: ORD-21 | B22: 10/24/2024 | C22: East | D22: Bradley Wiggins | E22: =IF(OR(K22="iPhone 15",K22="Samsung Galaxy"),"Mobiles",IF(OR(K22="HP Laptop",K22="Dell Laptop"),"Laptops","Accessories")) -> Laptops | F22: 16 | G22: 77212 | H22: Completed | I22: =TEXT(DATE(MID(B22,7,4),LEFT(B22,2),MID(B22,4,2)),"MMM") -> Oct | J22: =if(H22="Returned",0,L22) -> 1235392 | K22: Dell Laptop | L22: 1235392 | M22: =MONTH(DATE(MID(B22,7,4),LEFT(B22,2),MID(B22,4,2))) -> 10
A23: ORD-22 | B23: 09/18/2024 | C23: North | D23: Carey Oloshin | E23: =IF(OR(K23="iPhone 15",K23="Samsung Galaxy"),"Mobiles",IF(OR(K23="HP Laptop",K23="Dell Laptop"),"Laptops","Accessories")) -> Laptops | F23: 5 | G23: 78714 | H23: Returned | I23: =TEXT(DATE(MID(B23,7,4),LEFT(B23,2),MID(B23,4,2)),"MMM") -> Sep | J23: =if(H23="Returned",0,L23) -> 0 | K23: Dell Laptop | L23: 393570 | M23: =MONTH(DATE(MID(B23,7,4),LEFT(B23,2),MID(B23,4,2))) -> 9
A24: ORD-23 | B24: 03/29/2024 | C24: East | D24: Moreen Yeldham | E24: =IF(OR(K24="iPhone 15",K24="Samsung Galaxy"),"Mobiles",IF(OR(K24="HP Laptop",K24="Dell Laptop"),"Laptops","Accessories")) -> Laptops | F24: 2 | G24: 73168 | H24: Pending | I24: =TEXT(DATE(MID(B24,7,4),LEFT(B24,2),MID(B24,4,2)),"MMM") -> Mar | J24: =if(H24="Returned",0,L24) -> 146336 | K24: HP Laptop | L24: 146336 | M24: =MONTH(DATE(MID(B24,7,4),LEFT(B24,2),MID(B24,4,2))) -> 3
A25: ORD-24 | B25: 45512 | C25: South | D25: Trula Cobbin | E25: =IF(OR(K25="iPhone 15",K25="Samsung Galaxy"),"Mobiles",IF(OR(K25="HP Laptop",K25="Dell Laptop"),"Laptops","Accessories")) -> Laptops | F25: 8 | G25: 42894 | H25: Returned | I25: =TEXT(DATE(MID(B25,7,4),LEFT(B25,2),MID(B25,4,2)),"MMM") -> Aug | J25: =if(H25="Returned",0,L25) -> 0 | K25: Dell Laptop | L25: 343152 | M25: =MONTH(DATE(MID(B25,7,4),LEFT(B25,2),MID(B25,4,2))) -> 8
A26: ORD-25 | B26: 45355 | C26: South | D26: Lizette Hadye | E26: =IF(OR(K26="iPhone 15",K26="Samsung Galaxy"),"Mobiles",IF(OR(K26="HP Laptop",K26="Dell Laptop"),"Laptops","Accessories")) -> Accessories | F26: 5 | G26: 66731 | H26: Completed | I26: =TEXT(DATE(MID(B26,7,4),LEFT(B26,2),MID(B26,4,2)),"MMM") -> Apr | J26: =if(H26="Returned",0,L26) -> 333655 | K26: OnePlus TV | L26: 333655 | M26: =MONTH(DATE(MID(B26,7,4),LEFT(B26,2),MID(B26,4,2))) -> 4
A27: ORD-26 | B27: 03/23/2024 | C27: West | D27: Fey Walworth | E27: =IF(OR(K27="iPhone 15",K27="Samsung Galaxy"),"Mobiles",IF(OR(K27="HP Laptop",K27="Dell Laptop"),"Laptops","Accessories")) -> Accessories | F27: 4 | G27: 73151 | H27: Completed | I27: =TEXT(DATE(MID(B27,7,4),LEFT(B27,2),MID(B27,4,2)),"MMM") -> Mar | J27: =if(H27="Returned",0,L27) -> 292604 | K27: OnePlus TV | L27: 292604 | M27: =MONTH(DATE(MID(B27,7,4),LEFT(B27,2),MID(B27,4,2))) -> 3
A28: ORD-27 | B28: 45298 | C28: South | D28: Casper Tixall | E28: =IF(OR(K28="iPhone 15",K28="Samsung Galaxy"),"Mobiles",IF(OR(K28="HP Laptop",K28="Dell Laptop"),"Laptops","Accessories")) -> Accessories | F28: 10 | G28: 18040 | H28: Completed | I28: =TEXT(DATE(MID(B28,7,4),LEFT(B28,2),MID(B28,4,2)),"MMM") -> Jul | J28: =if(H28="Returned",0,L28) -> 180400 | K28: Boat Earbuds | L28: 180400 | M28: =MONTH(DATE(MID(B28,7,4),LEFT(B28,2),MID(B28,4,2))) -> 7
A29: ORD-28 | B29: 45323 | C29: East | D29: Chance Abbiss | E29: =IF(OR(K29="iPhone 15",K29="Samsung Galaxy"),"Mobiles",IF(OR(K29="HP Laptop",K29="Dell Laptop"),"Laptops","Accessories")) -> Accessories | F29: 8 | G29: 79316 | H29: Completed | I29: =TEXT(DATE(MID(B29,7,4),LEFT(B29,2),MID(B29,4,2)),"MMM") -> Jan | J29: =if(H29="Returned",0,L29) -> 634528 | K29: OnePlus TV | L29: 634528 | M29: =MONTH(DATE(MID(B29,7,4),LEFT(B29,2),MID(B29,4,2))) -> 1
A30: ORD-29 | B30: 01/27/2024 | C30: North | D30: Kelley Carren | E30: =IF(OR(K30="iPhone 15",K30="Samsung Galaxy"),"Mobiles",IF(OR(K30="HP Laptop",K30="Dell Laptop"),"Laptops","Accessories")) -> Mobiles | F30: 18 | G30: 27111 | H30: Pending | I30: =TEXT(DATE(MID(B30,7,4),LEFT(B30,2),MID(B30,4,2)),"MMM") -> Jan | J30: =if(H30="Returned",0,L30) -> 487998 | K30: iPhone 15 | L30: 487998 | M30: =MONTH(DATE(MID(B30,7,4),LEFT(B30,2),MID(B30,4,2))) -> 1
A31: ORD-30 | B31: 45424 | C31: West | D31: Royal Madner | E31: =IF(OR(K31="iPhone 15",K31="Samsung Galaxy"),"Mobiles",IF(OR(K31="HP Laptop",K31="Dell Laptop"),"Laptops","Accessories")) -> Mobiles | F31: 14 | G31: 55771 | H31: Pending | I31: =TEXT(DATE(MID(B31,7,4),LEFT(B31,2),MID(B31,4,2)),"MMM") -> Dec | J31: =if(H31="Returned",0,L31) -> 780794 | K31: iPhone 15 | L31: 780794 | M31: =MONTH(DATE(MID(B31,7,4),LEFT(B31,2),MID(B31,4,2))) -> 12
A32: ORD-31 | B32: 03/25/2024 | C32: East | D32: Christoper Maevela | E32: =IF(OR(K32="iPhone 15",K32="Samsung Galaxy"),"Mobiles",IF(OR(K32="HP Laptop",K32="Dell Laptop"),"Laptops","Accessories")) -> Accessories | F32: 6 | G32: 20955 | H32: Completed | I32: =TEXT(DATE(MID(B32,7,4),LEFT(B32,2),MID(B32,4,2)),"MMM") -> Mar | J32: =if(H32="Returned",0,L32) -> 125730 | K32: Logitech Mouse | L32: 125730 | M32: =MONTH(DATE(MID(B32,7,4),LEFT(B32,2),MID(B32,4,2))) -> 3
A33: ORD-32 | B33: 10/31/2024 | C33: West | D33: Torrie Targett | E33: =IF(OR(K33="iPhone 15",K33="Samsung Galaxy"),"Mobiles",IF(OR(K33="HP Laptop",K33="Dell Laptop"),"Laptops","Accessories")) -> Mobiles | F33: 9 | G33: 2998 | H33: Completed | I33: =TEXT(DATE(MID(B33,7,4),LEFT(B33,2),MID(B33,4,2)),"MMM") -> Oct | J33: =if(H33="Returned",0,L33) -> 26982 | K33: iPhone 15 | L33: 26982 | M33: =MONTH(DATE(MID(B33,7,4),LEFT(B33,2),MID(B33,4,2))) -> 10
A34: ORD-33 | B34: 45331 | C34: North | D34: Griffin Showl | E34: =IF(OR(K34="iPhone 15",K34="Samsung Galaxy"),"Mobiles",IF(OR(K34="HP Laptop",K34="Dell Laptop"),"Laptops","Accessories")) -> Mobiles | F34: 11 | G34: 65142 | H34: Pending | I34: =TEXT(DATE(MID(B34,7,4),LEFT(B34,2),MID(B34,4,2)),"MMM") -> Sep | J34: =if(H34="Returned",0,L34) -> 716562 | K34: Samsung Galaxy | L34: 716562 | M34: =MONTH(DATE(MID(B34,7,4),LEFT(B34,2),MID(B34,4,2))) -> 9
A35: ORD-34 | B35: 45601 | C35: South | D35: Eldredge Hair | E35: =IF(OR(K35="iPhone 15",K35="Samsung Galaxy"),"Mobiles",IF(OR(K35="HP Laptop",K35="Dell Laptop"),"Laptops","Accessories")) -> Accessories | F35: 17 | G35: 29927 | H35: Pending | I35: =TEXT(DATE(MID(B35,7,4),LEFT(B35,2),MID(B35,4,2)),"MMM") -> May | J35: =if(H35="Returned",0,L35) -> 508759 | K35: Logitech Mouse | L35: 508759 | M35: =MONTH(DATE(MID(B35,7,4),LEFT(B35,2),MID(B35,4,2))) -> 5
A36: ORD-35 | B36: 08/25/2024 | C36: West | D36: Gaspard Obbard | E36: =IF(OR(K36="iPhone 15",K36="Samsung Galaxy"),"Mobiles",IF(OR(K36="HP Laptop",K36="Dell Laptop"),"Laptops","Accessories")) -> Mobiles | F36: 9 | G36: 46394 | H36: Completed | I36: =TEXT(DATE(MID(B36,7,4),LEFT(B36,2),MID(B36,4,2)),"MMM") -> Aug | J36: =if(H36="Returned",0,L36) -> 417546 | K36: iPhone 15 | L36: 417546 | M36: =MONTH(DATE(MID(B36,7,4),LEFT(B36,2),MID(B36,4,2))) -> 8
A37: ORD-36 | B37: 45598 | C37: North | D37: Clari Pablo | E37: =IF(OR(K37="iPhone 15",K37="Samsung Galaxy"),"Mobiles",IF(OR(K37="HP Laptop",K37="Dell Laptop"),"Laptops","Accessories")) -> Mobiles | F37: 2 | G37: 39851 | H37: Pending | I37: =TEXT(DATE(MID(B37,7,4),LEFT(B37,2),MID(B37,4,2)),"MMM") -> Feb | J37: =if(H37="Returned",0,L37) -> 79702 | K37: iPhone 15 | L37: 79702 | M37: =MONTH(DATE(MID(B37,7,4),LEFT(B37,2),MID(B37,4,2))) -> 2
A38: ORD-37 | B38: 45602 | C38: West | D38: Bordy Morilla | E38: =IF(OR(K38="iPhone 15",K38="Samsung Galaxy"),"Mobiles",IF(OR(K38="HP Laptop",K38="Dell Laptop"),"Laptops","Accessories")) -> Mobiles | F38: 19 | G38: 16416 | H38: Returned | I38: =TEXT(DATE(MID(B38,7,4),LEFT(B38,2),MID(B38,4,2)),"MMM") -> Jun | J38: =if(H38="Returned",0,L38) -> 0 | K38: iPhone 15 | L38: 311904 | M38: =MONTH(DATE(MID(B38,7,4),LEFT(B38,2),MID(B38,4,2))) -> 6
A39: ORD-38 | B39: 04/29/2024 | C39: East | D39: Giustino Thorne | E39: =IF(OR(K39="iPhone 15",K39="Samsung Galaxy"),"Mobiles",IF(OR(K39="HP Laptop",K39="Dell Laptop"),"Laptops","Accessories")) -> Accessories | F39: 2 | G39: 34042 | H39: Pending | I39: =TEXT(DATE(MID(B39,7,4),LEFT(B39,2),MID(B39,4,2)),"MMM") -> Apr | J39: =if(H39="Returned",0,L39) -> 68084 | K39: OnePlus TV | L39: 68084 | M39: =MONTH(DATE(MID(B39,7,4),LEFT(B39,2),MID(B39,4,2))) -> 4
A40: ORD-39 | B40: 11/14/2024 | C40: West | D40: Winnifred Pocklington | E40: =IF(OR(K40="iPhone 15",K40="Samsung Galaxy"),"Mobiles",IF(OR(K40="HP Laptop",K40="Dell Laptop"),"Laptops","Accessories")) -> Mobiles | F40: 15 | G40: 53601 | H40: Returned | I40: =TEXT(DATE(MID(B40,7,4),LEFT(B40,2),MID(B40,4,2)),"MMM") -> Nov | J40: =if(H40="Returned",0,L40) -> 0 | K40: iPhone 15 | L40: 804015 | M40: =MONTH(DATE(MID(B40,7,4),LEFT(B40,2),MID(B40,4,2))) -> 11
...

Sheet Analysis
A1: Total revenue for the year | B1: =sum(Sales!J2:J301) -> 88015803
A3: Revenue broken down by each region | B3: North | C3: =SUMIF(Sales!C:C,"north",Sales!J:J) -> 17765314
B4: East | C4: =SUMIF(Sales!C:C,"east",Sales!J:J) -> 23604410
B5: West | C5: =SUMIF(Sales!C:C,"west",Sales!J:J) -> 20271674
B6: South | C6: =SUMIF(Sales!C:C,"south",Sales!J:J) -> 26374405
A8: Best performing salesperson | B8: {=INDEX(Sales!D:D,MATCH(MAX(Sales!J:J),Sales!J:J,0))} -> Britney Siddaley
A10: No. of orders returned | B10: =COUNTIF(Sales!H:H,"returned") -> 88
A12: highest sales month | B12: Dec
A14: average order value per category | B14: Mobiles | C14: =AVERAGEIF(Sales!E:E,"mobiles",Sales!J:J) -> 294196.69
B15: Accessories | C15: =AVERAGEIF(Sales!E:E,"accessories",Sales!J:J) -> 257216.39
B16: Laptops | C16: =AVERAGEIF(Sales!E:E,"laptops",Sales!J:J) -> 357815.19
A18: Top Product by Revenue | B18: {=INDEX(Sales!K:K,MATCH(MAX(SUMIF(Sales!K:K,Sales!K:K,Sales!J:J)),SUMIF(Sales!K:K,Sales!K:K,Sales!J:J),0))} -> iPhone 15
A20: Salesperson with Most Orders | B20: =Analysis!B8 -> Britney Siddaley
A22: Completion Rate by Region | B22: North | C22: =(COUNTIFS(Sales!C:C,"north",Sales!H:H,"completed")/COUNTIF(Sales!C:C,"north")*100) -> 33.333333
B23: East | C23: =(COUNTIFS(Sales!C:C,"east",Sales!H:H,"completed")/COUNTIF(Sales!C:C,"east")*100) -> 32.5
B24: West | C24: =COUNTIFS(Sales!C:C,"West",Sales!H:H,"Completed")/COUNTIF(Sales!C:C,"West")*100 -> 31.944444
B25: South | C25: =(COUNTIFS(Sales!C:C,"south",Sales!H:H,"completed")/COUNTIF(Sales!C:C,"south")*100) -> 27.848101
A27: Most Common Product Sold | B27: {=INDEX(Sales!K:K,MATCH(MAX(COUNTIF(Sales!K:K,Sales!K:K)),COUNTIF(Sales!K:K,Sales!K:K),0))} -> iPhone 15

Sheet Region_Month

Sheet Salesperson

Sheet Category

Sheet Order_Status

Sheet Total_category_Revenue

Sheet Dashboard
A12: Total Revenue | B12: Total Orders | C12: Best Salesperson | D12: Return Rate
A13: =SUM(Sales!J:J) -> 88015803 | B13: 300 | C13: =Analysis!B8 -> Britney Siddaley | D13: 0.29
